<?xml version='1.0'?>

<robot name="cart" xmlns:xacro="http://www.ros.org/wiki/xacro">

  <!-- <xacro:include filename="$(find lego_robot)/urdf/my_robot.gazebo" /> -->

  <link name="front_left_wheel_dummy"/>

  <joint name="front_left_wheel_steer" type="revolute">
    <origin rpy="-1.57079 -0.08726  0" xyz="0.5   0.298 0.15"/>
    <parent link="chassis"/>
    <child link="front_left_wheel_dummy"/>
    <axis xyz="0 -1 0"/>
    <limit effort="0" lower="-0.610865238198" upper="0.610865238198" velocity="0"/>
  </joint>

  <joint name="front_left_wheel_spin" type="continuous">
    <parent link="front_left_wheel_dummy"/>
    <child link="front_left_wheel"/>
    <axis xyz="0 0 1"/>
    <limit effort="0.0" lower="-0" upper="0" velocity="0.0"/>
  </joint>

  <joint name="front_right_wheel_spin" type="continuous">
    <parent link="chassis"/>
    <child link="front_right_wheel"/>
    <origin rpy="-1.57079 -0.08726  0" xyz="0.5   -0.298  0.15"/>
    <axis xyz="0 0 1"/>
    <limit effort="0.0" lower="-0.610865238198" upper="0.610865238198" velocity="0.0"/>
  </joint>

  <!-- <link name="front_right_wheel_steer_spin__revolute_dummy_link"/>
  <joint name="front_right_wheel_steer_spin__revolute_dummy_joint" type="revolute">
    <parent link="front_right_wheel_steer_spin__revolute_dummy_link"/>
    <child link="front_right_wheel"/>
    <axis xyz="0 0 1"/>
    <limit effort="0" lower="0" upper="0" velocity="0"/>
  </joint> -->

  <joint name="rear_left_wheel_spin" type="continuous">
    <parent link="chassis"/>
    <child link="rear_left_wheel"/>
    <origin rpy="-1.57079  0       0" xyz="-0.5    0.298  0.15"/>
    <axis xyz="0 0 1"/>
    <limit effort="0" lower="0" upper="0" velocity="0"/>
  </joint>

  <joint name="rear_right_wheel_spin" type="continuous">
    <parent link="chassis"/>
    <child link="rear_right_wheel"/>
    <origin rpy="-1.57079  0       0" xyz="-0.5   -0.298  0.15"/>
    <axis xyz="0 0 1"/>
    <limit effort="0" lower="0" upper="0" velocity="0"/>
  </joint>

  <link name="chassis">
    <inertial>
      <mass value="10"/>
      <origin rpy="0 0 0" xyz="0.1 0  0"/>
      <inertia ixx="0.21666666666666667" ixy="0" ixz="0" iyy="0.8416666666666667" iyz="0" izz="1.0416666666666667"/>
    </inertial>
    <collision name="collision">
      <origin rpy="0 0 0" xyz="0   0   0.15"/>
      <geometry>
        <box size="1.0 0.5 0.1"/>
      </geometry>
    </collision>
    <visual name="visual">
      <origin rpy="0 0 0" xyz="0   0   0.15"/>
      <geometry>
        <box size="1.0 0.5 0.1"/>
      </geometry>
    </visual>
  </link>

  <link name="front_left_wheel">
    <inertial>
      <mass value="0.5"/>
      <origin rpy="0 0 0" xyz="0 0 0"/>
      <inertia ixx="0.0030791666666666667" ixy="0" ixz="0" iyy="0.0030791666666666667" iyz="0" izz="0.005625"/>
    </inertial>
    <collision name="collision">
      <origin rpy="0 0 0" xyz="0 0 0"/>
      <geometry>
        <cylinder length="0.08" radius="0.15"/>
      </geometry>
    </collision>
    <visual name="visual">
      <origin rpy="0 0 0" xyz="0 0 0"/>
      <geometry>
        <cylinder length="0.08" radius="0.15"/>
      </geometry>
    </visual>
  </link>

  <link name="front_right_wheel">
    <inertial>
      <mass value="0.5"/>
      <origin rpy="0 0 0" xyz="0 0 0"/>
      <inertia ixx="0.0030791666666666667" ixy="0" ixz="0" iyy="0.0030791666666666667" iyz="0" izz="0.005625"/>
    </inertial>
    <collision name="collision">
      <origin rpy="0 0 0" xyz="0 0 0"/>
      <geometry>
        <cylinder length="0.08" radius="0.15"/>
      </geometry>
    </collision>
    <visual name="visual">
      <origin rpy="0 0 0" xyz="0 0 0"/>
      <geometry>
        <cylinder length="0.08" radius="0.15"/>
      </geometry>
    </visual>
  </link>

  <link name="rear_left_wheel">
    <inertial>
      <mass value="0.5"/>
      <origin rpy="0 0 0" xyz="0 0 0"/>
      <inertia ixx="0.0030791666666666667" ixy="0" ixz="0" iyy="0.0030791666666666667" iyz="0" izz="0.005625"/>
    </inertial>
    <collision name="collision">
      <origin rpy="0 0 0" xyz="0 0 0"/>
      <geometry>
        <cylinder length="0.08" radius="0.15"/>
      </geometry>
    </collision>
    <visual name="visual">
      <origin rpy="0 0 0" xyz="0 0 0"/>
      <geometry>
        <cylinder length="0.08" radius="0.15"/>
      </geometry>
    </visual>
  </link>

  <link name="rear_right_wheel">
    <inertial>
      <mass value="0.5"/>
      <origin rpy="0 0 0" xyz="0 0 0"/>
      <inertia ixx="0.0030791666666666667" ixy="0" ixz="0" iyy="0.0030791666666666667" iyz="0" izz="0.005625"/>
    </inertial>
    <collision name="collision">
      <origin rpy="0 0 0" xyz="0 0 0"/>
      <geometry>
        <cylinder length="0.08" radius="0.15"/>
      </geometry>
    </collision>
    <visual name="visual">
      <origin rpy="0 0 0" xyz="0 0 0"/>
      <geometry>
        <cylinder length="0.08" radius="0.15"/>
      </geometry>
    </visual>
  </link>
</robot>
